Workbook

Sheet clean pnl
A1: Line Item | B1: Fiscal Year | C1: Value
A2: revenue | B2: 2016
A3: wholesale | B3: 2016 | C3: 11663
A4: retail | B4: 2016 | C4: 5841
A5: other businesses | B5: 2016 | C5: 979
A6: total net revenue | B6: 2016 | C6: 18483
A7: revenue growth y/y | B7: 2016
A8: cost of goods sold | B8: 2016 | C8: -9500
A9: gross profit | B9: 2016 | C9: 8983
A10: gross margin % | B10: 2016 | C10: 0.486
A11: royalty and commission income | B11: 2016 | C11: 108
A12: other operating income | B12: 2016 | C12: 60
A13: other operating expenses | B13: 2016
A14: marketing and point-of-sale | B14: 2016 | C14: -2532
A15: distribution and selling expense | B15: 2016 | C15: -4029
A16: general & administration | B16: 2016 | C16: -998
A17: sundry expenses | B17: 2016 | C17: -185
A18: total other operating exp. | B18: 2016 | C18: -7744
A19: goodwill / intangible impairment | B19: 2016
A20: operating profit (ebit) | B20: 2016 | C20: 1407
A21: operating margin % | B21: 2016 | C21: 0.076
A22: financial income | B22: 2016 | C22: 20
A23: financial expenses | B23: 2016 | C23: -74
A24: income before taxes | B24: 2016 | C24: 1353
A25: income tax expense | B25: 2016 | C25: -392
A26: effective tax rate % | B26: 2016 | C26: 0.29
A27: net income from continuing ops. | B27: 2016 | C27: 961
A28: net income from disc. operations | B28: 2016
A29: net income (total) | B29: 2016 | C29: 961
A30: less: minority interest | B30: 2016 | C30: -12
A31: net income attrib. to shareholders | B31: 2016 | C31: 949
A32: basic eps | B32: 2016 | C32: 4.72
A33: diluted eps | B33: 2016 | C33: 4.7
A34: wtd. avg shares - basic (mn) | B34: 2016 | C34: 201
A35: wtd. avg shares - diluted (mn) | B35: 2016 | C35: 201.8
A36: dividend per share (dps) | B36: 2016 | C36: 2
A37: revenue | B37: 2017
A38: wholesale | B38: 2017 | C38: 12943
A39: retail | B39: 2017 | C39: 7172
A40: other businesses | B40: 2017 | C40: 1103
...

Sheet lookup tables
A1: Line Item Description | B1: Statement Group | C1: Sign Convention
A2: Wholesale | B2: Revenue | C2: Positive
A3: Retail | B3: Revenue | C3: Positive
A4: Other Businesses | B4: Revenue | C4: Positive
A5: Total Net Revenue | B5: Revenue | C5: Positive
A6: Cost of Goods Sold | B6: Cost | C6: Negative
A7: Gross Profit | B7: Subtotal | C7: Positive
A8: Royalty and Commission Income | B8: Other income | C8: Positive
A9: Other Operating Income | B9: Other income | C9: Positive
A10: Marketing and Point-of-Sale | B10: Operating expense | C10: Negative
A11: Distribution and Selling Expense | B11: Operating expense | C11: Negative
A12: General & Administration | B12: Operating expense | C12: Negative
... A28: Dividend Per Share (DPS) | B28: Per share | C28: Positive

Sheet MASTER P&L
A1: Line Item | B1: FY2016 | C1: FY2017 | D1: FY2018 | E1: FY2019 | F1: FY2020 | G1: FY2021 | H1: FY2022 | I1: FY2023
A2: revenue
A3: wholesale | B3: {=IF($A3="","",_xlfn.XLOOKUP(1,(Table1[Line Item]=$A3)*(Table1[Fiscal Year]=VALUE(RIGHT(B$1,4))),Table1[Value],"Not found"))} -> 11663 | C3: {=IF($A3="","",_xlfn.XLOOKUP(1,(Table1[Line Item]=$A3)*(Table1[Fiscal Year]=VALUE(RIGHT(C$1,4))),Table1[Value],"Not found"))} -> 12943 | D3: {=IF($A3="","",_xlfn.XLOOKUP(1,(Table1[Line Item]=$A3)*(Table1[Fiscal Year]=VALUE(RIGHT(D$1,4))),Table1[Value],"Not found"))} -> 12733 | E3: {=IF($A3="","",_xlfn.XLOOKUP(1,(Table1[Line Item]=$A3)*(Table1[Fiscal Year]=VALUE(RIGHT(E$1,4))),Table1[Value],"Not found"))} -> 13191 | F3: {=IF($A3="","",_xlfn.XLOOKUP(1,(Table1[Line Item]=$A3)*(Table1[Fiscal Year]=VALUE(RIGHT(F$1,4))),Table1[Value],"Not found"))} -> 10160 | G3: {=IF($A3="","",_xlfn.XLOOKUP(1,(Table1[Line Item]=$A3)*(Table1[Fiscal Year]=VALUE(RIGHT(G$1,4))),Table1[Value],"Not found"))} -> 11148 | H3: {=IF($A3="","",_xlfn.XLOOKUP(1,(Table1[Line Item]=$A3)*(Table1[Fiscal Year]=VALUE(RIGHT(H$1,4))),Table1[Value],"Not found"))} -> 12156 | I3: {=IF($A3="","",_xlfn.XLOOKUP(1,(Table1[Line Item]=$A3)*(Table1[Fiscal Year]=VALUE(RIGHT(I$1,4))),Table1[Value],"Not found"))} -> 11142
A4: retail | B4: {=IF($A4="","",_xlfn.XLOOKUP(1,(Table1[Line Item]=$A4)*(Table1[Fiscal Year]=VALUE(RIGHT(B$1,4))),Table1[Value],"Not found"))} -> 5841 | C4: {=IF($A4="","",_xlfn.XLOOKUP(1,(Table1[Line Item]=$A4)*(Table1[Fiscal Year]=VALUE(RIGHT(C$1,4))),Table1[Value],"Not found"))} -> 7172 | D4: {=IF($A4="","",_xlfn.XLOOKUP(1,(Table1[Line Item]=$A4)*(Table1[Fiscal Year]=VALUE(RIGHT(D$1,4))),Table1[Value],"Not found"))} -> 8196 | E4: {=IF($A4="","",_xlfn.XLOOKUP(1,(Table1[Line Item]=$A4)*(Table1[Fiscal Year]=VALUE(RIGHT(E$1,4))),Table1[Value],"Not found"))} -> 9480 | F4: {=IF($A4="","",_xlfn.XLOOKUP(1,(Table1[Line Item]=$A4)*(Table1[Fiscal Year]=VALUE(RIGHT(F$1,4))),Table1[Value],"Not found"))} -> 8970 | G4: {=IF($A4="","",_xlfn.XLOOKUP(1,(Table1[Line Item]=$A4)*(Table1[Fiscal Year]=VALUE(RIGHT(G$1,4))),Table1[Value],"Not found"))} -> 9428 | H4: {=IF($A4="","",_xlfn.XLOOKUP(1,(Table1[Line Item]=$A4)*(Table1[Fiscal Year]=VALUE(RIGHT(H$1,4))),Table1[Value],"Not found"))} -> 9725 | I4: {=IF($A4="","",_xlfn.XLOOKUP(1,(Table1[Line Item]=$A4)*(Table1[Fiscal Year]=VALUE(RIGHT(I$1,4))),Table1[Value],"Not found"))} -> 9706
A5: other businesses | B5: {=IF($A5="","",_xlfn.XLOOKUP(1,(Table1[Line Item]=$A5)*(Table1[Fiscal Year]=VALUE(RIGHT(B$1,4))),Table1[Value],"Not found"))} -> 979 | C5: {=IF($A5="","",_xlfn.XLOOKUP(1,(Table1[Line Item]=$A5)*(Table1[Fiscal Year]=VALUE(RIGHT(C$1,4))),Table1[Value],"Not found"))} -> 1103 | D5: {=IF($A5="","",_xlfn.XLOOKUP(1,(Table1[Line Item]=$A5)*(Table1[Fiscal Year]=VALUE(RIGHT(D$1,4))),Table1[Value],"Not found"))} -> 986 | E5: {=IF($A5="","",_xlfn.XLOOKUP(1,(Table1[Line Item]=$A5)*(Table1[Fiscal Year]=VALUE(RIGHT(E$1,4))),Table1[Value],"Not found"))} -> 969 | F5: {=IF($A5="","",_xlfn.XLOOKUP(1,(Table1[Line Item]=$A5)*(Table1[Fiscal Year]=VALUE(RIGHT(F$1,4))),Table1[Value],"Not found"))} -> 714 | G5: {=IF($A5="","",_xlfn.XLOOKUP(1,(Table1[Line Item]=$A5)*(Table1[Fiscal Year]=VALUE(RIGHT(G$1,4))),Table1[Value],"Not found"))} -> 658 | H5: {=IF($A5="","",_xlfn.XLOOKUP(1,(Table1[Line Item]=$A5)*(Table1[Fiscal Year]=VALUE(RIGHT(H$1,4))),Table1[Value],"Not found"))} -> 630 | I5: {=IF($A5="","",_xlfn.XLOOKUP(1,(Table1[Line Item]=$A5)*(Table1[Fiscal Year]=VALUE(RIGHT(I$1,4))),Table1[Value],"Not found"))} -> 579
A6: total net revenue | B6: {=IF($A6="","",_xlfn.XLOOKUP(1,(Table1[Line Item]=$A6)*(Table1[Fiscal Year]=VALUE(RIGHT(B$1,4))),Table1[Value],"Not found"))} -> 18483 | C6: {=IF($A6="","",_xlfn.XLOOKUP(1,(Table1[Line Item]=$A6)*(Table1[Fiscal Year]=VALUE(RIGHT(C$1,4))),Table1[Value],"Not found"))} -> 21218 | D6: {=IF($A6="","",_xlfn.XLOOKUP(1,(Table1[Line Item]=$A6)*(Table1[Fiscal Year]=VALUE(RIGHT(D$1,4))),Table1[Value],"Not found"))} -> 21915 | E6: {=IF($A6="","",_xlfn.XLOOKUP(1,(Table1[Line Item]=$A6)*(Table1[Fiscal Year]=VALUE(RIGHT(E$1,4))),Table1[Value],"Not found"))} -> 23640 | F6: {=IF($A6="","",_xlfn.XLOOKUP(1,(Table1[Line Item]=$A6)*(Table1[Fiscal Year]=VALUE(RIGHT(F$1,4))),Table1[Value],"Not found"))} -> 19844 | G6: {=IF($A6="","",_xlfn.XLOOKUP(1,(Table1[Line Item]=$A6)*(Table1[Fiscal Year]=VALUE(RIGHT(G$1,4))),Table1[Value],"Not found"))} -> 21234 | H6: {=IF($A6="","",_xlfn.XLOOKUP(1,(Table1[Line Item]=$A6)*(Table1[Fiscal Year]=VALUE(RIGHT(H$1,4))),Table1[Value],"Not found"))} -> 22511 | I6: {=IF($A6="","",_xlfn.XLOOKUP(1,(Table1[Line Item]=$A6)*(Table1[Fiscal Year]=VALUE(RIGHT(I$1,4))),Table1[Value],"Not found"))} -> 21427
A7: revenue growth y/y | B7: {=IF($A7="","",_xlfn.XLOOKUP(1,(Table1[Line Item]=$A7)*(Table1[Fiscal Year]=VALUE(RIGHT(B$1,4))),Table1[Value],"Not found"))} -> 0 | C7: {=IF($A7="","",_xlfn.XLOOKUP(1,(Table1[Line Item]=$A7)*(Table1[Fiscal Year]=VALUE(RIGHT(C$1,4))),Table1[Value],"Not found"))} -> 0.148 | D7: {=IF($A7="","",_xlfn.XLOOKUP(1,(Table1[Line Item]=$A7)*(Table1[Fiscal Year]=VALUE(RIGHT(D$1,4))),Table1[Value],"Not found"))} -> 0.033 | E7: {=IF($A7="","",_xlfn.XLOOKUP(1,(Table1[Line Item]=$A7)*(Table1[Fiscal Year]=VALUE(RIGHT(E$1,4))),Table1[Value],"Not found"))} -> 0.079 | F7: {=IF($A7="","",_xlfn.XLOOKUP(1,(Table1[Line Item]=$A7)*(Table1[Fiscal Year]=VALUE(RIGHT(F$1,4))),Table1[Value],"Not found"))} -> -0.161 | G7: {=IF($A7="","",_xlfn.XLOOKUP(1,(Table1[Line Item]=$A7)*(Table1[Fiscal Year]=VALUE(RIGHT(G$1,4))),Table1[Value],"Not found"))} -> 0.07 | H7: {=IF($A7="","",_xlfn.XLOOKUP(1,(Table1[Line Item]=$A7)*(Table1[Fiscal Year]=VALUE(RIGHT(H$1,4))),Table1[Value],"Not found"))} -> 0.06 | I7: {=IF($A7="","",_xlfn.XLOOKUP(1,(Table1[Line Item]=$A7)*(Table1[Fiscal Year]=VALUE(RIGHT(I$1,4))),Table1[Value],"Not found"))} -> -0.048
B8: {=IF($A8="","",_xlfn.XLOOKUP(1,(Table1[Line Item]=$A8)*(Table1[Fiscal Year]=VALUE(RIGHT(B$1,4))),Table1[Value],"Not found"))} | C8: {=IF($A8="","",_xlfn.XLOOKUP(1,(Table1[Line Item]=$A8)*(Table1[Fiscal Year]=VALUE(RIGHT(C$1,4))),Table1[Value],"Not found"))} | D8: {=IF($A8="","",_xlfn.XLOOKUP(1,(Table1[Line Item]=$A8)*(Table1[Fiscal Year]=VALUE(RIGHT(D$1,4))),Table1[Value],"Not found"))} | E8: {=IF($A8="","",_xlfn.XLOOKUP(1,(Table1[Line Item]=$A8)*(Table1[Fiscal Year]=VALUE(RIGHT(E$1,4))),Table1[Value],"Not found"))} | F8: {=IF($A8="","",_xlfn.XLOOKUP(1,(Table1[Line Item]=$A8)*(Table1[Fiscal Year]=VALUE(RIGHT(F$1,4))),Table1[Value],"Not found"))} | G8: {=IF($A8="","",_xlfn.XLOOKUP(1,(Table1[Line Item]=$A8)*(Table1[Fiscal Year]=VALUE(RIGHT(G$1,4))),Table1[Value],"Not found"))} | H8: {=IF($A8="","",_xlfn.XLOOKUP(1,(Table1[Line Item]=$A8)*(Table1[Fiscal Year]=VALUE(RIGHT(H$1,4))),Table1[Value],"Not found"))} | I8: {=IF($A8="","",_xlfn.XLOOKUP(1,(Table1[Line Item]=$A8)*(Table1[Fiscal Year]=VALUE(RIGHT(I$1,4))),Table1[Value],"Not found"))}
A9: cost of goods sold | B9: {=IF($A9="","",_xlfn.XLOOKUP(1,(Table1[Line Item]=$A9)*(Table1[Fiscal Year]=VALUE(RIGHT(B$1,4))),Table1[Value],"Not found"))} -> -9500 | C9: {=IF($A9="","",_xlfn.XLOOKUP(1,(Table1[Line Item]=$A9)*(Table1[Fiscal Year]=VALUE(RIGHT(C$1,4))),Table1[Value],"Not found"))} -> -10524 | D9: {=IF($A9="","",_xlfn.XLOOKUP(1,(Table1[Line Item]=$A9)*(Table1[Fiscal Year]=VALUE(RIGHT(D$1,4))),Table1[Value],"Not found"))} -> -10607 | E9: {=IF($A9="","",_xlfn.XLOOKUP(1,(Table1[Line Item]=$A9)*(Table1[Fiscal Year]=VALUE(RIGHT(E$1,4))),Table1[Value],"Not found"))} -> -11347 | F9: {=IF($A9="","",_xlfn.XLOOKUP(1,(Table1[Line Item]=$A9)*(Table1[Fiscal Year]=VALUE(RIGHT(F$1,4))),Table1[Value],"Not found"))} -> -9982 | G9: {=IF($A9="","",_xlfn.XLOOKUP(1,(Table1[Line Item]=$A9)*(Table1[Fiscal Year]=VALUE(RIGHT(G$1,4))),Table1[Value],"Not found"))} -> -10511 | H9: {=IF($A9="","",_xlfn.XLOOKUP(1,(Table1[Line Item]=$A9)*(Table1[Fiscal Year]=VALUE(RIGHT(H$1,4))),Table1[Value],"Not found"))} -> -11863 | I9: {=IF($A9="","",_xlfn.XLOOKUP(1,(Table1[Line Item]=$A9)*(Table1[Fiscal Year]=VALUE(RIGHT(I$1,4))),Table1[Value],"Not found"))} -> -11249
A10: gross profit | B10: {=IF($A10="","",_xlfn.XLOOKUP(1,(Table1[Line Item]=$A10)*(Table1[Fiscal Year]=VALUE(RIGHT(B$1,4))),Table1[Value],"Not found"))} -> 8983 | C10: {=IF($A10="","",_xlfn.XLOOKUP(1,(Table1[Line Item]=$A10)*(Table1[Fiscal Year]=VALUE(RIGHT(C$1,4))),Table1[Value],"Not found"))} -> 10694 | D10: {=IF($A10="","",_xlfn.XLOOKUP(1,(Table1[Line Item]=$A10)*(Table1[Fiscal Year]=VALUE(RIGHT(D$1,4))),Table1[Value],"Not found"))} -> 11308 | E10: {=IF($A10="","",_xlfn.XLOOKUP(1,(Table1[Line Item]=$A10)*(Table1[Fiscal Year]=VALUE(RIGHT(E$1,4))),Table1[Value],"Not found"))} -> 12293 | F10: {=IF($A10="","",_xlfn.XLOOKUP(1,(Table1[Line Item]=$A10)*(Table1[Fiscal Year]=VALUE(RIGHT(F$1,4))),Table1[Value],"Not found"))} -> 9862 | G10: {=IF($A10="","",_xlfn.XLOOKUP(1,(Table1[Line Item]=$A10)*(Table1[Fiscal Year]=VALUE(RIGHT(G$1,4))),Table1[Value],"Not found"))} -> 10723 | H10: {=IF($A10="","",_xlfn.XLOOKUP(1,(Table1[Line Item]=$A10)*(Table1[Fiscal Year]=VALUE(RIGHT(H$1,4))),Table1[Value],"Not found"))} -> 10648 | I10: {=IF($A10="","",_xlfn.XLOOKUP(1,(Table1[Line Item]=$A10)*(Table1[Fiscal Year]=VALUE(RIGHT(I$1,4))),Table1[Value],"Not found"))} -> 10178
A11: gross margin % | B11: {=IF($A11="","",_xlfn.XLOOKUP(1,(Table1[Line Item]=$A11)*(Table1[Fiscal Year]=VALUE(RIGHT(B$1,4))),Table1[Value],"Not found"))} -> 0.486 | C11: {=IF($A11="","",_xlfn.XLOOKUP(1,(Table1[Line Item]=$A11)*(Table1[Fiscal Year]=VALUE(RIGHT(C$1,4))),Table1[Value],"Not found"))} -> 0.504 | D11: {=IF($A11="","",_xlfn.XLOOKUP(1,(Table1[Line Item]=$A11)*(Table1[Fiscal Year]=VALUE(RIGHT(D$1,4))),Table1[Value],"Not found"))} -> 0.516 | E11: {=IF($A11="","",_xlfn.XLOOKUP(1,(Table1[Line Item]=$A11)*(Table1[Fiscal Year]=VALUE(RIGHT(E$1,4))),Table1[Value],"Not found"))} -> 0.52 | F11: {=IF($A11="","",_xlfn.XLOOKUP(1,(Table1[Line Item]=$A11)*(Table1[Fiscal Year]=VALUE(RIGHT(F$1,4))),Table1[Value],"Not found"))} -> 0.497 | G11: {=IF($A11="","",_xlfn.XLOOKUP(1,(Table1[Line Item]=$A11)*(Table1[Fiscal Year]=VALUE(RIGHT(G$1,4))),Table1[Value],"Not found"))} -> 0.505 | H11: {=IF($A11="","",_xlfn.XLOOKUP(1,(Table1[Line Item]=$A11)*(Table1[Fiscal Year]=VALUE(RIGHT(H$1,4))),Table1[Value],"Not found"))} -> 0.473 | I11: {=IF($A11="","",_xlfn.XLOOKUP(1,(Table1[Line Item]=$A11)*(Table1[Fiscal Year]=VALUE(RIGHT(I$1,4))),Table1[Value],"Not found"))} -> 0.475
B12: {=IF($A12="","",_xlfn.XLOOKUP(1,(Table1[Line Item]=$A12)*(Table1[Fiscal Year]=VALUE(RIGHT(B$1,4))),Table1[Value],"Not found"))} | C12: {=IF($A12="","",_xlfn.XLOOKUP(1,(Table1[Line Item]=$A12)*(Table1[Fiscal Year]=VALUE(RIGHT(C$1,4))),Table1[Value],"Not found"))} | D12: {=IF($A12="","",_xlfn.XLOOKUP(1,(Table1[Line Item]=$A12)*(Table1[Fiscal Year]=VALUE(RIGHT(D$1,4))),Table1[Value],"Not found"))} | E12: {=IF($A12="","",_xlfn.XLOOKUP(1,(Table1[Line Item]=$A12)*(Table1[Fiscal Year]=VALUE(RIGHT(E$1,4))),Table1[Value],"Not found"))} | F12: {=IF($A12="","",_xlfn.XLOOKUP(1,(Table1[Line Item]=$A12)*(Table1[Fiscal Year]=VALUE(RIGHT(F$1,4))),Table1[Value],"Not found"))} | G12: {=IF($A12="","",_xlfn.XLOOKUP(1,(Table1[Line Item]=$A12)*(Table1[Fiscal Year]=VALUE(RIGHT(G$1,4))),Table1[Value],"Not found"))} | H12: {=IF($A12="","",_xlfn.XLOOKUP(1,(Table1[Line Item]=$A12)*(Table1[Fiscal Year]=VALUE(RIGHT(H$1,4))),Table1[Value],"Not found"))} | I12: {=IF($A12="","",_xlfn.XLOOKUP(1,(Table1[Line Item]=$A12)*(Table1[Fiscal Year]=VALUE(RIGHT(I$1,4))),Table1[Value],"Not found"))}
A13: royalty and commission income | B13: {=IF($A13="","",_xlfn.XLOOKUP(1,(Table1[Line Item]=$A13)*(Table1[Fiscal Year]=VALUE(RIGHT(B$1,4))),Table1[Value],"Not found"))} -> 108 | C13: {=IF($A13="","",_xlfn.XLOOKUP(1,(Table1[Line Item]=$A13)*(Table1[Fiscal Year]=VALUE(RIGHT(C$1,4))),Table1[Value],"Not found"))} -> 115 | D13: {=IF($A13="","",_xlfn.XLOOKUP(1,(Table1[Line Item]=$A13)*(Table1[Fiscal Year]=VALUE(RIGHT(D$1,4))),Table1[Value],"Not found"))} -> 121 | E13: {=IF($A13="","",_xlfn.XLOOKUP(1,(Table1[Line Item]=$A13)*(Table1[Fiscal Year]=VALUE(RIGHT(E$1,4))),Table1[Value],"Not found"))} -> 130 | F13: {=IF($A13="","",_xlfn.XLOOKUP(1,(Table1[Line Item]=$A13)*(Table1[Fiscal Year]=VALUE(RIGHT(F$1,4))),Table1[Value],"Not found"))} -> 96 | G13: {=IF($A13="","",_xlfn.XLOOKUP(1,(Table1[Line Item]=$A13)*(Table1[Fiscal Year]=VALUE(RIGHT(G$1,4))),Table1[Value],"Not found"))} -> 104 | H13: {=IF($A13="","",_xlfn.XLOOKUP(1,(Table1[Line Item]=$A13)*(Table1[Fiscal Year]=VALUE(RIGHT(H$1,4))),Table1[Value],"Not found"))} -> 112 | I13: {=IF($A13="","",_xlfn.XLOOKUP(1,(Table1[Line Item]=$A13)*(Table1[Fiscal Year]=VALUE(RIGHT(I$1,4))),Table1[Value],"Not found"))} -> 107
A14: other operating income | B14: {=IF($A14="","",_xlfn.XLOOKUP(1,(Table1[Line Item]=$A14)*(Table1[Fiscal Year]=VALUE(RIGHT(B$1,4))),Table1[Value],"Not found"))} -> 60 | C14: {=IF($A14="","",_xlfn.XLOOKUP(1,(Table1[Line Item]=$A14)*(Table1[Fiscal Year]=VALUE(RIGHT(C$1,4))),Table1[Value],"Not found"))} -> 66 | D14: {=IF($A14="","",_xlfn.XLOOKUP(1,(Table1[Line Item]=$A14)*(Table1[Fiscal Year]=VALUE(RIGHT(D$1,4))),Table1[Value],"Not found"))} -> 71 | E14: {=IF($A14="","",_xlfn.XLOOKUP(1,(Table1[Line Item]=$A14)*(Table1[Fiscal Year]=VALUE(RIGHT(E$1,4))),Table1[Value],"Not found"))} -> 78 | F14: {=IF($A14="","",_xlfn.XLOOKUP(1,(Table1[Line Item]=$A14)*(Table1[Fiscal Year]=VALUE(RIGHT(F$1,4))),Table1[Value],"Not found"))} -> 52 | G14: {=IF($A14="","",_xlfn.XLOOKUP(1,(Table1[Line Item]=$A14)*(Table1[Fiscal Year]=VALUE(RIGHT(G$1,4))),Table1[Value],"Not found"))} -> 58 | H14: {=IF($A14="","",_xlfn.XLOOKUP(1,(Table1[Line Item]=$A14)*(Table1[Fiscal Year]=VALUE(RIGHT(H$1,4))),Table1[Value],"Not found"))} -> 63 | I14: {=IF($A14="","",_xlfn.XLOOKUP(1,(Table1[Line Item]=$A14)*(Table1[Fiscal Year]=VALUE(RIGHT(I$1,4))),Table1[Value],"Not found"))} -> 55
A15: marketing and point-of-sale | B15: {=IF($A15="","",_xlfn.XLOOKUP(1,(Table1[Line Item]=$A15)*(Table1[Fiscal Year]=VALUE(RIGHT(B$1,4))),Table1[Value],"Not found"))} -> -2532 | C15: {=IF($A15="","",_xlfn.XLOOKUP(1,(Table1[Line Item]=$A15)*(Table1[Fiscal Year]=VALUE(RIGHT(C$1,4))),Table1[Value],"Not found"))} -> -2843 | D15: {=IF($A15="","",_xlfn.XLOOKUP(1,(Table1[Line Item]=$A15)*(Table1[Fiscal Year]=VALUE(RIGHT(D$1,4))),Table1[Value],"Not found"))} -> -2871 | E15: {=IF($A15="","",_xlfn.XLOOKUP(1,(Table1[Line Item]=$A15)*(Table1[Fiscal Year]=VALUE(RIGHT(E$1,4))),Table1[Value],"Not found"))} -> -3026 | F15: {=IF($A15="","",_xlfn.XLOOKUP(1,(Table1[Line Item]=$A15)*(Table1[Fiscal Year]=VALUE(RIGHT(F$1,4))),Table1[Value],"Not found"))} -> -2361 | G15: {=IF($A15="","",_xlfn.XLOOKUP(1,(Table1[Line Item]=$A15)*(Table1[Fiscal Year]=VALUE(RIGHT(G$1,4))),Table1[Value],"Not found"))} -> -2569 | H15: {=IF($A15="","",_xlfn.XLOOKUP(1,(Table1[Line Item]=$A15)*(Table1[Fiscal Year]=VALUE(RIGHT(H$1,4))),Table1[Value],"Not found"))} -> -2791 | I15: {=IF($A15="","",_xlfn.XLOOKUP(1,(Table1[Line Item]=$A15)*(Table1[Fiscal Year]=VALUE(RIGHT(I$1,4))),Table1[Value],"Not found"))} -> -2636
A16: distribution and selling expense | B16: {=IF($A16="","",_xlfn.XLOOKUP(1,(Table1[Line Item]=$A16)*(Table1[Fiscal Year]=VALUE(RIGHT(B$1,4))),Table1[Value],"Not found"))} -> -4029 | C16: {=IF($A16="","",_xlfn.XLOOKUP(1,(Table1[Line Item]=$A16)*(Table1[Fiscal Year]=VALUE(RIGHT(C$1,4))),Table1[Value],"Not found"))} -> -4710 | D16: {=IF($A16="","",_xlfn.XLOOKUP(1,(Table1[Line Item]=$A16)*(Table1[Fiscal Year]=VALUE(RIGHT(D$1,4))),Table1[Value],"Not found"))} -> -4909 | E16: {=IF($A16="","",_xlfn.XLOOKUP(1,(Table1[Line Item]=$A16)*(Table1[Fiscal Year]=VALUE(RIGHT(E$1,4))),Table1[Value],"Not found"))} -> -5272 | F16: {=IF($A16="","",_xlfn.XLOOKUP(1,(Table1[Line Item]=$A16)*(Table1[Fiscal Year]=VALUE(RIGHT(F$1,4))),Table1[Value],"Not found"))} -> -5358 | G16: {=IF($A16="","",_xlfn.XLOOKUP(1,(Table1[Line Item]=$A16)*(Table1[Fiscal Year]=VALUE(RIGHT(G$1,4))),Table1[Value],"Not found"))} -> -4969 | H16: {=IF($A16="","",_xlfn.XLOOKUP(1,(Table1[Line Item]=$A16)*(Table1[Fiscal Year]=VALUE(RIGHT(H$1,4))),Table1[Value],"Not found"))} -> -5470 | I16: {=IF($A16="","",_xlfn.XLOOKUP(1,(Table1[Line Item]=$A16)*(Table1[Fiscal Year]=VALUE(RIGHT(I$1,4))),Table1[Value],"Not found"))} -> -5528
A17: general & administration | B17: {=IF($A17="","",_xlfn.XLOOKUP(1,(Table1[Line Item]=$A17)*(Table1[Fiscal Year]=VALUE(RIGHT(B$1,4))),Table1[Value],"Not found"))} -> -998 | C17: {=IF($A17="","",_xlfn.XLOOKUP(1,(Table1[Line Item]=$A17)*(Table1[Fiscal Year]=VALUE(RIGHT(C$1,4))),Table1[Value],"Not found"))} -> -1125 | D17: {=IF($A17="","",_xlfn.XLOOKUP(1,(Table1[Line Item]=$A17)*(Table1[Fiscal Year]=VALUE(RIGHT(D$1,4))),Table1[Value],"Not found"))} -> -1140 | E17: {=IF($A17="","",_xlfn.XLOOKUP(1,(Table1[Line Item]=$A17)*(Table1[Fiscal Year]=VALUE(RIGHT(E$1,4))),Table1[Value],"Not found"))} -> -1347 | F17: {=IF($A17="","",_xlfn.XLOOKUP(1,(Table1[Line Item]=$A17)*(Table1[Fiscal Year]=VALUE(RIGHT(F$1,4))),Table1[Value],"Not found"))} -> -1290 | G17: {=IF($A17="","",_xlfn.XLOOKUP(1,(Table1[Line Item]=$A17)*(Table1[Fiscal Year]=VALUE(RIGHT(G$1,4))),Table1[Value],"Not found"))} -> -1295 | H17: {=IF($A17="","",_xlfn.XLOOKUP(1,(Table1[Line Item]=$A17)*(Table1[Fiscal Year]=VALUE(RIGHT(H$1,4))),Table1[Value],"Not found"))} -> -1756 | I17: {=IF($A17="","",_xlfn.XLOOKUP(1,(Table1[Line Item]=$A17)*(Table1[Fiscal Year]=VALUE(RIGHT(I$1,4))),Table1[Value],"Not found"))} -> -1564
A18: sundry expenses | B18: {=IF($A18="","",_xlfn.XLOOKUP(1,(Table1[Line Item]=$A18)*(Table1[Fiscal Year]=VALUE(RIGHT(B$1,4))),Table1[Value],"Not found"))} -> -185 | C18: {=IF($A18="","",_xlfn.XLOOKUP(1,(Table1[Line Item]=$A18)*(Table1[Fiscal Year]=VALUE(RIGHT(C$1,4))),Table1[Value],"Not found"))} -> -212 | D18: {=IF($A18="","",_xlfn.XLOOKUP(1,(Table1[Line Item]=$A18)*(Table1[Fiscal Year]=VALUE(RIGHT(D$1,4))),Table1[Value],"Not found"))} -> -219 | E18: {=IF($A18="","",_xlfn.XLOOKUP(1,(Table1[Line Item]=$A18)*(Table1[Fiscal Year]=VALUE(RIGHT(E$1,4))),Table1[Value],"Not found"))} -> -236 | F18: {=IF($A18="","",_xlfn.XLOOKUP(1,(Table1[Line Item]=$A18)*(Table1[Fiscal Year]=VALUE(RIGHT(F$1,4))),Table1[Value],"Not found"))} -> -198 | G18: {=IF($A18="","",_xlfn.XLOOKUP(1,(Table1[Line Item]=$A18)*(Table1[Fiscal Year]=VALUE(RIGHT(G$1,4))),Table1[Value],"Not found"))} -> -212 | H18: {=IF($A18="","",_xlfn.XLOOKUP(1,(Table1[Line Item]=$A18)*(Table1[Fiscal Year]=VALUE(RIGHT(H$1,4))),Table1[Value],"Not found"))} -> -225 | I18: {=IF($A18="","",_xlfn.XLOOKUP(1,(Table1[Line Item]=$A18)*(Table1[Fiscal Year]=VALUE(RIGHT(I$1,4))),Table1[Value],"Not found"))} -> -257
A19: total other operating exp. | B19: {=IF($A19="","",_xlfn.XLOOKUP(1,(Table1[Line Item]=$A19)*(Table1[Fiscal Year]=VALUE(RIGHT(B$1,4))),Table1[Value],"Not found"))} -> -7744 | C19: {=IF($A19="","",_xlfn.XLOOKUP(1,(Table1[Line Item]=$A19)*(Table1[Fiscal Year]=VALUE(RIGHT(C$1,4))),Table1[Value],"Not found"))} -> -8890 | D19: {=IF($A19="","",_xlfn.XLOOKUP(1,(Table1[Line Item]=$A19)*(Table1[Fiscal Year]=VALUE(RIGHT(D$1,4))),Table1[Value],"Not found"))} -> -9139 | E19: {=IF($A19="","",_xlfn.XLOOKUP(1,(Table1[Line Item]=$A19)*(Table1[Fiscal Year]=VALUE(RIGHT(E$1,4))),Table1[Value],"Not found"))} -> -9881 | F19: {=IF($A19="","",_xlfn.XLOOKUP(1,(Table1[Line Item]=$A19)*(Table1[Fiscal Year]=VALUE(RIGHT(F$1,4))),Table1[Value],"Not found"))} -> -9207 | G19: {=IF($A19="","",_xlfn.XLOOKUP(1,(Table1[Line Item]=$A19)*(Table1[Fiscal Year]=VALUE(RIGHT(G$1,4))),Table1[Value],"Not found"))} -> -9045 | H19: {=IF($A19="","",_xlfn.XLOOKUP(1,(Table1[Line Item]=$A19)*(Table1[Fiscal Year]=VALUE(RIGHT(H$1,4))),Table1[Value],"Not found"))} -> -10242 | I19: {=IF($A19="","",_xlfn.XLOOKUP(1,(Table1[Line Item]=$A19)*(Table1[Fiscal Year]=VALUE(RIGHT(I$1,4))),Table1[Value],"Not found"))} -> -9985
A20: goodwill / intangible impairment | B20: {=IF($A20="","",_xlfn.XLOOKUP(1,(Table1[Line Item]=$A20)*(Table1[Fiscal Year]=VALUE(RIGHT(B$1,4))),Table1[Value],"Not found"))} -> 0 | C20: {=IF($A20="","",_xlfn.XLOOKUP(1,(Table1[Line Item]=$A20)*(Table1[Fiscal Year]=VALUE(RIGHT(C$1,4))),Table1[Value],"Not found"))} -> 0 | D20: {=IF($A20="","",_xlfn.XLOOKUP(1,(Table1[Line Item]=$A20)*(Table1[Fiscal Year]=VALUE(RIGHT(D$1,4))),Table1[Value],"Not found"))} -> 0 | E20: {=IF($A20="","",_xlfn.XLOOKUP(1,(Table1[Line Item]=$A20)*(Table1[Fiscal Year]=VALUE(RIGHT(E$1,4))),Table1[Value],"Not found"))} -> 0 | F20: {=IF($A20="","",_xlfn.XLOOKUP(1,(Table1[Line Item]=$A20)*(Table1[Fiscal Year]=VALUE(RIGHT(F$1,4))),Table1[Value],"Not found"))} -> 0 | G20: {=IF($A20="","",_xlfn.XLOOKUP(1,(Table1[Line Item]=$A20)*(Table1[Fiscal Year]=VALUE(RIGHT(G$1,4))),Table1[Value],"Not found"))} -> 0 | H20: {=IF($A20="","",_xlfn.XLOOKUP(1,(Table1[Line Item]=$A20)*(Table1[Fiscal Year]=VALUE(RIGHT(H$1,4))),Table1[Value],"Not found"))} -> -194 | I20: {=IF($A20="","",_xlfn.XLOOKUP(1,(Table1[Line Item]=$A20)*(Table1[Fiscal Year]=VALUE(RIGHT(I$1,4))),Table1[Value],"Not found"))} -> 0
B21: {=IF($A21="","",_xlfn.XLOOKUP(1,(Table1[Line Item]=$A21)*(Table1[Fiscal Year]=VALUE(RIGHT(B$1,4))),Table1[Value],"Not found"))} | C21: {=IF($A21="","",_xlfn.XLOOKUP(1,(Table1[Line Item]=$A21)*(Table1[Fiscal Year]=VALUE(RIGHT(C$1,4))),Table1[Value],"Not found"))} | D21: {=IF($A21="","",_xlfn.XLOOKUP(1,(Table1[Line Item]=$A21)*(Table1[Fiscal Year]=VALUE(RIGHT(D$1,4))),Table1[Value],"Not found"))} | E21: {=IF($A21="","",_xlfn.XLOOKUP(1,(Table1[Line Item]=$A21)*(Table1[Fiscal Year]=VALUE(RIGHT(E$1,4))),Table1[Value],"Not found"))} | F21: {=IF($A21="","",_xlfn.XLOOKUP(1,(Table1[Line Item]=$A21)*(Table1[Fiscal Year]=VALUE(RIGHT(F$1,4))),Table1[Value],"Not found"))} | G21: {=IF($A21="","",_xlfn.XLOOKUP(1,(Table1[Line Item]=$A21)*(Table1[Fiscal Year]=VALUE(RIGHT(G$1,4))),Table1[Value],"Not found"))} | H21: {=IF($A21="","",_xlfn.XLOOKUP(1,(Table1[Line Item]=$A21)*(Table1[Fiscal Year]=VALUE(RIGHT(H$1,4))),Table1[Value],"Not found"))} | I21: {=IF($A21="","",_xlfn.XLOOKUP(1,(Table1[Line Item]=$A21)*(Table1[Fiscal Year]=VALUE(RIGHT(I$1,4))),Table1[Value],"Not found"))}
A22: operating profit (ebit) | B22: {=IF($A22="","",_xlfn.XLOOKUP(1,(Table1[Line Item]=$A22)*(Table1[Fiscal Year]=VALUE(RIGHT(B$1,4))),Table1[Value],"Not found"))} -> 1407 | C22: {=IF($A22="","",_xlfn.XLOOKUP(1,(Table1[Line Item]=$A22)*(Table1[Fiscal Year]=VALUE(RIGHT(C$1,4))),Table1[Value],"Not found"))} -> 1985 | D22: {=IF($A22="","",_xlfn.XLOOKUP(1,(Table1[Line Item]=$A22)*(Table1[Fiscal Year]=VALUE(RIGHT(D$1,4))),Table1[Value],"Not found"))} -> 2361 | E22: {=IF($A22="","",_xlfn.XLOOKUP(1,(Table1[Line Item]=$A22)*(Table1[Fiscal Year]=VALUE(RIGHT(E$1,4))),Table1[Value],"Not found"))} -> 2620 | F22: {=IF($A22="","",_xlfn.XLOOKUP(1,(Table1[Line Item]=$A22)*(Table1[Fiscal Year]=VALUE(RIGHT(F$1,4))),Table1[Value],"Not found"))} -> 803 | G22: {=IF($A22="","",_xlfn.XLOOKUP(1,(Table1[Line Item]=$A22)*(Table1[Fiscal Year]=VALUE(RIGHT(G$1,4))),Table1[Value],"Not found"))} -> 1840 | H22: {=IF($A22="","",_xlfn.XLOOKUP(1,(Table1[Line Item]=$A22)*(Table1[Fiscal Year]=VALUE(RIGHT(H$1,4))),Table1[Value],"Not found"))} -> 387 | I22: {=IF($A22="","",_xlfn.XLOOKUP(1,(Table1[Line Item]=$A22)*(Table1[Fiscal Year]=VALUE(RIGHT(I$1,4))),Table1[Value],"Not found"))} -> 355
A23: operating margin % | B23: {=IF($A23="","",_xlfn.XLOOKUP(1,(Table1[Line Item]=$A23)*(Table1[Fiscal Year]=VALUE(RIGHT(B$1,4))),Table1[Value],"Not found"))} -> 0.076 | C23: {=IF($A23="","",_xlfn.XLOOKUP(1,(Table1[Line Item]=$A23)*(Table1[Fiscal Year]=VALUE(RIGHT(C$1,4))),Table1[Value],"Not found"))} -> 0.094 | D23: {=IF($A23="","",_xlfn.XLOOKUP(1,(Table1[Line Item]=$A23)*(Table1[Fiscal Year]=VALUE(RIGHT(D$1,4))),Table1[Value],"Not found"))} -> 0.108 | E23: {=IF($A23="","",_xlfn.XLOOKUP(1,(Table1[Line Item]=$A23)*(Table1[Fiscal Year]=VALUE(RIGHT(E$1,4))),Table1[Value],"Not found"))} -> 0.111 | F23: {=IF($A23="","",_xlfn.XLOOKUP(1,(Table1[Line Item]=$A23)*(Table1[Fiscal Year]=VALUE(RIGHT(F$1,4))),Table1[Value],"Not found"))} -> 0.04 | G23: {=IF($A23="","",_xlfn.XLOOKUP(1,(Table1[Line Item]=$A23)*(Table1[Fiscal Year]=VALUE(RIGHT(G$1,4))),Table1[Value],"Not found"))} -> 0.087 | H23: {=IF($A23="","",_xlfn.XLOOKUP(1,(Table1[Line Item]=$A23)*(Table1[Fiscal Year]=VALUE(RIGHT(H$1,4))),Table1[Value],"Not found"))} -> 0.017 | I23: {=IF($A23="","",_xlfn.XLOOKUP(1,(Table1[Line Item]=$A23)*(Table1[Fiscal Year]=VALUE(RIGHT(I$1,4))),Table1[Value],"Not found"))} -> 0.017
B24: {=IF($A24="","",_xlfn.XLOOKUP(1,(Table1[Line Item]=$A24)*(Table1[Fiscal Year]=VALUE(RIGHT(B$1,4))),Table1[Value],"Not found"))} | C24: {=IF($A24="","",_xlfn.XLOOKUP(1,(Table1[Line Item]=$A24)*(Table1[Fiscal Year]=VALUE(RIGHT(C$1,4))),Table1[Value],"Not found"))} | D24: {=IF($A24="","",_xlfn.XLOOKUP(1,(Table1[Line Item]=$A24)*(Table1[Fiscal Year]=VALUE(RIGHT(D$1,4))),Table1[Value],"Not found"))} | E24: {=IF($A24="","",_xlfn.XLOOKUP(1,(Table1[Line Item]=$A24)*(Table1[Fiscal Year]=VALUE(RIGHT(E$1,4))),Table1[Value],"Not found"))} | F24: {=IF($A24="","",_xlfn.XLOOKUP(1,(Table1[Line Item]=$A24)*(Table1[Fiscal Year]=VALUE(RIGHT(F$1,4))),Table1[Value],"Not found"))} | G24: {=IF($A24="","",_xlfn.XLOOKUP(1,(Table1[Line Item]=$A24)*(Table1[Fiscal Year]=VALUE(RIGHT(G$1,4))),Table1[Value],"Not found"))} | H24: {=IF($A24="","",_xlfn.XLOOKUP(1,(Table1[Line Item]=$A24)*(Table1[Fiscal Year]=VALUE(RIGHT(H$1,4))),Table1[Value],"Not found"))} | I24: {=IF($A24="","",_xlfn.XLOOKUP(1,(Table1[Line Item]=$A24)*(Table1[Fiscal Year]=VALUE(RIGHT(I$1,4))),Table1[Value],"Not found"))}
A25: financial income | B25: {=IF($A25="","",_xlfn.XLOOKUP(1,(Table1[Line Item]=$A25)*(Table1[Fiscal Year]=VALUE(RIGHT(B$1,4))),Table1[Value],"Not found"))} -> 20 | C25: {=IF($A25="","",_xlfn.XLOOKUP(1,(Table1[Line Item]=$A25)*(Table1[Fiscal Year]=VALUE(RIGHT(C$1,4))),Table1[Value],"Not found"))} -> 24 | D25: {=IF($A25="","",_xlfn.XLOOKUP(1,(Table1[Line Item]=$A25)*(Table1[Fiscal Year]=VALUE(RIGHT(D$1,4))),Table1[Value],"Not found"))} -> 28 | E25: {=IF($A25="","",_xlfn.XLOOKUP(1,(Table1[Line Item]=$A25)*(Table1[Fiscal Year]=VALUE(RIGHT(E$1,4))),Table1[Value],"Not found"))} -> 32 | F25: {=IF($A25="","",_xlfn.XLOOKUP(1,(Table1[Line Item]=$A25)*(Table1[Fiscal Year]=VALUE(RIGHT(F$1,4))),Table1[Value],"Not found"))} -> 26 | G25: {=IF($A25="","",_xlfn.XLOOKUP(1,(Table1[Line Item]=$A25)*(Table1[Fiscal Year]=VALUE(RIGHT(G$1,4))),Table1[Value],"Not found"))} -> 30 | H25: {=IF($A25="","",_xlfn.XLOOKUP(1,(Table1[Line Item]=$A25)*(Table1[Fiscal Year]=VALUE(RIGHT(H$1,4))),Table1[Value],"Not found"))} -> 44 | I25: {=IF($A25="","",_xlfn.XLOOKUP(1,(Table1[Line Item]=$A25)*(Table1[Fiscal Year]=VALUE(RIGHT(I$1,4))),Table1[Value],"Not found"))} -> 62
A26: financial expenses | B26: {=IF($A26="","",_xlfn.XLOOKUP(1,(Table1[Line Item]=$A26)*(Table1[Fiscal Year]=VALUE(RIGHT(B$1,4))),Table1[Value],"Not found"))} -> -74 | C26: {=IF($A26="","",_xlfn.XLOOKUP(1,(Table1[Line Item]=$A26)*(Table1[Fiscal Year]=VALUE(RIGHT(C$1,4))),Table1[Value],"Not found"))} -> -82 | D26: {=IF($A26="","",_xlfn.XLOOKUP(1,(Table1[Line Item]=$A26)*(Table1[Fiscal Year]=VALUE(RIGHT(D$1,4))),Table1[Value],"Not found"))} -> -91 | E26: {=IF($A26="","",_xlfn.XLOOKUP(1,(Table1[Line Item]=$A26)*(Table1[Fiscal Year]=VALUE(RIGHT(E$1,4))),Table1[Value],"Not found"))} -> -166 | F26: {=IF($A26="","",_xlfn.XLOOKUP(1,(Table1[Line Item]=$A26)*(Table1[Fiscal Year]=VALUE(RIGHT(F$1,4))),Table1[Value],"Not found"))} -> -178 | G26: {=IF($A26="","",_xlfn.XLOOKUP(1,(Table1[Line Item]=$A26)*(Table1[Fiscal Year]=VALUE(RIGHT(G$1,4))),Table1[Value],"Not found"))} -> -172 | H26: {=IF($A26="","",_xlfn.XLOOKUP(1,(Table1[Line Item]=$A26)*(Table1[Fiscal Year]=VALUE(RIGHT(H$1,4))),Table1[Value],"Not found"))} -> -199 | I26: {=IF($A26="","",_xlfn.XLOOKUP(1,(Table1[Line Item]=$A26)*(Table1[Fiscal Year]=VALUE(RIGHT(I$1,4))),Table1[Value],"Not found"))} -> -242
A27: income before taxes | B27: {=IF($A27="","",_xlfn.XLOOKUP(1,(Table1[Line Item]=$A27)*(Table1[Fiscal Year]=VALUE(RIGHT(B$1,4))),Table1[Value],"Not found"))} -> 1353 | C27: {=IF($A27="","",_xlfn.XLOOKUP(1,(Table1[Line Item]=$A27)*(Table1[Fiscal Year]=VALUE(RIGHT(C$1,4))),Table1[Value],"Not found"))} -> 1927 | D27: {=IF($A27="","",_xlfn.XLOOKUP(1,(Table1[Line Item]=$A27)*(Table1[Fiscal Year]=VALUE(RIGHT(D$1,4))),Table1[Value],"Not found"))} -> 2298 | E27: {=IF($A27="","",_xlfn.XLOOKUP(1,(Table1[Line Item]=$A27)*(Table1[Fiscal Year]=VALUE(RIGHT(E$1,4))),Table1[Value],"Not found"))} -> 2486 | F27: {=IF($A27="","",_xlfn.XLOOKUP(1,(Table1[Line Item]=$A27)*(Table1[Fiscal Year]=VALUE(RIGHT(F$1,4))),Table1[Value],"Not found"))} -> 651 | G27: {=IF($A27="","",_xlfn.XLOOKUP(1,(Table1[Line Item]=$A27)*(Table1[Fiscal Year]=VALUE(RIGHT(G$1,4))),Table1[Value],"Not found"))} -> 1698 | H27: {=IF($A27="","",_xlfn.XLOOKUP(1,(Table1[Line Item]=$A27)*(Table1[Fiscal Year]=VALUE(RIGHT(H$1,4))),Table1[Value],"Not found"))} -> 232 | I27: {=IF($A27="","",_xlfn.XLOOKUP(1,(Table1[Line Item]=$A27)*(Table1[Fiscal Year]=VALUE(RIGHT(I$1,4))),Table1[Value],"Not found"))} -> 175
A28: income tax expense | B28: {=IF($A28="","",_xlfn.XLOOKUP(1,(Table1[Line Item]=$A28)*(Table1[Fiscal Year]=VALUE(RIGHT(B$1,4))),Table1[Value],"Not found"))} -> -392 | C28: {=IF($A28="","",_xlfn.XLOOKUP(1,(Table1[Line Item]=$A28)*(Table1[Fiscal Year]=VALUE(RIGHT(C$1,4))),Table1[Value],"Not found"))} -> -540 | D28: {=IF($A28="","",_xlfn.XLOOKUP(1,(Table1[Line Item]=$A28)*(Table1[Fiscal Year]=VALUE(RIGHT(D$1,4))),Table1[Value],"Not found"))} -> -597 | E28: {=IF($A28="","",_xlfn.XLOOKUP(1,(Table1[Line Item]=$A28)*(Table1[Fiscal Year]=VALUE(RIGHT(E$1,4))),Table1[Value],"Not found"))} -> -622 | F28: {=IF($A28="","",_xlfn.XLOOKUP(1,(Table1[Line Item]=$A28)*(Table1[Fiscal Year]=VALUE(RIGHT(F$1,4))),Table1[Value],"Not found"))} -> -228 | G28: {=IF($A28="","",_xlfn.XLOOKUP(1,(Table1[Line Item]=$A28)*(Table1[Fiscal Year]=VALUE(RIGHT(G$1,4))),Table1[Value],"Not found"))} -> -475 | H28: {=IF($A28="","",_xlfn.XLOOKUP(1,(Table1[Line Item]=$A28)*(Table1[Fiscal Year]=VALUE(RIGHT(H$1,4))),Table1[Value],"Not found"))} -> -174 | I28: {=IF($A28="","",_xlfn.XLOOKUP(1,(Table1[Line Item]=$A28)*(Table1[Fiscal Year]=VALUE(RIGHT(I$1,4))),Table1[Value],"Not found"))} -> -201
A29: effective tax rate % | B29: {=IF($A29="","",_xlfn.XLOOKUP(1,(Table1[Line Item]=$A29)*(Table1[Fiscal Year]=VALUE(RIGHT(B$1,4))),Table1[Value],"Not found"))} -> 0.29 | C29: {=IF($A29="","",_xlfn.XLOOKUP(1,(Table1[Line Item]=$A29)*(Table1[Fiscal Year]=VALUE(RIGHT(C$1,4))),Table1[Value],"Not found"))} -> 0.28 | D29: {=IF($A29="","",_xlfn.XLOOKUP(1,(Table1[Line Item]=$A29)*(Table1[Fiscal Year]=VALUE(RIGHT(D$1,4))),Table1[Value],"Not found"))} -> 0.26 | E29: {=IF($A29="","",_xlfn.XLOOKUP(1,(Table1[Line Item]=$A29)*(Table1[Fiscal Year]=VALUE(RIGHT(E$1,4))),Table1[Value],"Not found"))} -> 0.25 | F29: {=IF($A29="","",_xlfn.XLOOKUP(1,(Table1[Line Item]=$A29)*(Table1[Fiscal Year]=VALUE(RIGHT(F$1,4))),Table1[Value],"Not found"))} -> 0.35 | G29: {=IF($A29="","",_xlfn.XLOOKUP(1,(Table1[Line Item]=$A29)*(Table1[Fiscal Year]=VALUE(RIGHT(G$1,4))),Table1[Value],"Not found"))} -> 0.28 | H29: {=IF($A29="","",_xlfn.XLOOKUP(1,(Table1[Line Item]=$A29)*(Table1[Fiscal Year]=VALUE(RIGHT(H$1,4))),Table1[Value],"Not found"))} -> 0.75 | I29: {=IF($A29="","",_xlfn.XLOOKUP(1,(Table1[Line Item]=$A29)*(Table1[Fiscal Year]=VALUE(RIGHT(I$1,4))),Table1[Value],"Not found"))} -> 1.149
B30: {=IF($A30="","",_xlfn.XLOOKUP(1,(Table1[Line Item]=$A30)*(Table1[Fiscal Year]=VALUE(RIGHT(B$1,4))),Table1[Value],"Not found"))} | C30: {=IF($A30="","",_xlfn.XLOOKUP(1,(Table1[Line Item]=$A30)*(Table1[Fiscal Year]=VALUE(RIGHT(C$1,4))),Table1[Value],"Not found"))} | D30: {=IF($A30="","",_xlfn.XLOOKUP(1,(Table1[Line Item]=$A30)*(Table1[Fiscal Year]=VALUE(RIGHT(D$1,4))),Table1[Value],"Not found"))} | E30: {=IF($A30="","",_xlfn.XLOOKUP(1,(Table1[Line Item]=$A30)*(Table1[Fiscal Year]=VALUE(RIGHT(E$1,4))),Table1[Value],"Not found"))} | F30: {=IF($A30="","",_xlfn.XLOOKUP(1,(Table1[Line Item]=$A30)*(Table1[Fiscal Year]=VALUE(RIGHT(F$1,4))),Table1[Value],"Not found"))} | G30: {=IF($A30="","",_xlfn.XLOOKUP(1,(Table1[Line Item]=$A30)*(Table1[Fiscal Year]=VALUE(RIGHT(G$1,4))),Table1[Value],"Not found"))} | H30: {=IF($A30="","",_xlfn.XLOOKUP(1,(Table1[Line Item]=$A30)*(Table1[Fiscal Year]=VALUE(RIGHT(H$1,4))),Table1[Value],"Not found"))} | I30: {=IF($A30="","",_xlfn.XLOOKUP(1,(Table1[Line Item]=$A30)*(Table1[Fiscal Year]=VALUE(RIGHT(I$1,4))),Table1[Value],"Not found"))}
A31: net income from continuing ops. | B31: {=IF($A31="","",_xlfn.XLOOKUP(1,(Table1[Line Item]=$A31)*(Table1[Fiscal Year]=VALUE(RIGHT(B$1,4))),Table1[Value],"Not found"))} -> 961 | C31: {=IF($A31="","",_xlfn.XLOOKUP(1,(Table1[Line Item]=$A31)*(Table1[Fiscal Year]=VALUE(RIGHT(C$1,4))),Table1[Value],"Not found"))} -> 1387 | D31: {=IF($A31="","",_xlfn.XLOOKUP(1,(Table1[Line Item]=$A31)*(Table1[Fiscal Year]=VALUE(RIGHT(D$1,4))),Table1[Value],"Not found"))} -> 1701 | E31: {=IF($A31="","",_xlfn.XLOOKUP(1,(Table1[Line Item]=$A31)*(Table1[Fiscal Year]=VALUE(RIGHT(E$1,4))),Table1[Value],"Not found"))} -> 1864 | F31: {=IF($A31="","",_xlfn.XLOOKUP(1,(Table1[Line Item]=$A31)*(Table1[Fiscal Year]=VALUE(RIGHT(F$1,4))),Table1[Value],"Not found"))} -> 423 | G31: {=IF($A31="","",_xlfn.XLOOKUP(1,(Table1[Line Item]=$A31)*(Table1[Fiscal Year]=VALUE(RIGHT(G$1,4))),Table1[Value],"Not found"))} -> 1223 | H31: {=IF($A31="","",_xlfn.XLOOKUP(1,(Table1[Line Item]=$A31)*(Table1[Fiscal Year]=VALUE(RIGHT(H$1,4))),Table1[Value],"Not found"))} -> 58 | I31: {=IF($A31="","",_xlfn.XLOOKUP(1,(Table1[Line Item]=$A31)*(Table1[Fiscal Year]=VALUE(RIGHT(I$1,4))),Table1[Value],"Not found"))} -> -26
A32: net income (total) | B32: {=IF($A32="","",_xlfn.XLOOKUP(1,(Table1[Line Item]=$A32)*(Table1[Fiscal Year]=VALUE(RIGHT(B$1,4))),Table1[Value],"Not found"))} -> 961 | C32: {=IF($A32="","",_xlfn.XLOOKUP(1,(Table1[Line Item]=$A32)*(Table1[Fiscal Year]=VALUE(RIGHT(C$1,4))),Table1[Value],"Not found"))} -> 1387 | D32: {=IF($A32="","",_xlfn.XLOOKUP(1,(Table1[Line Item]=$A32)*(Table1[Fiscal Year]=VALUE(RIGHT(D$1,4))),Table1[Value],"Not found"))} -> 1701 | E32: {=IF($A32="","",_xlfn.XLOOKUP(1,(Table1[Line Item]=$A32)*(Table1[Fiscal Year]=VALUE(RIGHT(E$1,4))),Table1[Value],"Not found"))} -> 1864 | F32: {=IF($A32="","",_xlfn.XLOOKUP(1,(Table1[Line Item]=$A32)*(Table1[Fiscal Year]=VALUE(RIGHT(F$1,4))),Table1[Value],"Not found"))} -> 353 | G32: {=IF($A32="","",_xlfn.XLOOKUP(1,(Table1[Line Item]=$A32)*(Table1[Fiscal Year]=VALUE(RIGHT(G$1,4))),Table1[Value],"Not found"))} -> 1455 | H32: {=IF($A32="","",_xlfn.XLOOKUP(1,(Table1[Line Item]=$A32)*(Table1[Fiscal Year]=VALUE(RIGHT(H$1,4))),Table1[Value],"Not found"))} -> 58 | I32: {=IF($A32="","",_xlfn.XLOOKUP(1,(Table1[Line Item]=$A32)*(Table1[Fiscal Year]=VALUE(RIGHT(I$1,4))),Table1[Value],"Not found"))} -> -26
A33: less: minority interest | B33: {=IF($A33="","",_xlfn.XLOOKUP(1,(Table1[Line Item]=$A33)*(Table1[Fiscal Year]=VALUE(RIGHT(B$1,4))),Table1[Value],"Not found"))} -> -12 | C33: {=IF($A33="","",_xlfn.XLOOKUP(1,(Table1[Line Item]=$A33)*(Table1[Fiscal Year]=VALUE(RIGHT(C$1,4))),Table1[Value],"Not found"))} -> -14 | D33: {=IF($A33="","",_xlfn.XLOOKUP(1,(Table1[Line Item]=$A33)*(Table1[Fiscal Year]=VALUE(RIGHT(D$1,4))),Table1[Value],"Not found"))} -> -11 | E33: {=IF($A33="","",_xlfn.XLOOKUP(1,(Table1[Line Item]=$A33)*(Table1[Fiscal Year]=VALUE(RIGHT(E$1,4))),Table1[Value],"Not found"))} -> -9 | F33: {=IF($A33="","",_xlfn.XLOOKUP(1,(Table1[Line Item]=$A33)*(Table1[Fiscal Year]=VALUE(RIGHT(F$1,4))),Table1[Value],"Not found"))} -> -6 | G33: {=IF($A33="","",_xlfn.XLOOKUP(1,(Table1[Line Item]=$A33)*(Table1[Fiscal Year]=VALUE(RIGHT(G$1,4))),Table1[Value],"Not found"))} -> -8 | H33: {=IF($A33="","",_xlfn.XLOOKUP(1,(Table1[Line Item]=$A33)*(Table1[Fiscal Year]=VALUE(RIGHT(H$1,4))),Table1[Value],"Not found"))} -> -8 | I33: {=IF($A33="","",_xlfn.XLOOKUP(1,(Table1[Line Item]=$A33)*(Table1[Fiscal Year]=VALUE(RIGHT(I$1,4))),Table1[Value],"Not found"))} -> -7
A34: net income attrib. to shareholders | B34: {=IF($A34="","",_xlfn.XLOOKUP(1,(Table1[Line Item]=$A34)*(Table1[Fiscal Year]=VALUE(RIGHT(B$1,4))),Table1[Value],"Not found"))} -> 949 | C34: {=IF($A34="","",_xlfn.XLOOKUP(1,(Table1[Line Item]=$A34)*(Table1[Fiscal Year]=VALUE(RIGHT(C$1,4))),Table1[Value],"Not found"))} -> 1373 | D34: {=IF($A34="","",_xlfn.XLOOKUP(1,(Table1[Line Item]=$A34)*(Table1[Fiscal Year]=VALUE(RIGHT(D$1,4))),Table1[Value],"Not found"))} -> 1690 | E34: {=IF($A34="","",_xlfn.XLOOKUP(1,(Table1[Line Item]=$A34)*(Table1[Fiscal Year]=VALUE(RIGHT(E$1,4))),Table1[Value],"Not found"))} -> 1855 | F34: {=IF($A34="","",_xlfn.XLOOKUP(1,(Table1[Line Item]=$A34)*(Table1[Fiscal Year]=VALUE(RIGHT(F$1,4))),Table1[Value],"Not found"))} -> 347 | G34: {=IF($A34="","",_xlfn.XLOOKUP(1,(Table1[Line Item]=$A34)*(Table1[Fiscal Year]=VALUE(RIGHT(G$1,4))),Table1[Value],"Not found"))} -> 1447 | H34: {=IF($A34="","",_xlfn.XLOOKUP(1,(Table1[Line Item]=$A34)*(Table1[Fiscal Year]=VALUE(RIGHT(H$1,4))),Table1[Value],"Not found"))} -> 50 | I34: {=IF($A34="","",_xlfn.XLOOKUP(1,(Table1[Line Item]=$A34)*(Table1[Fiscal Year]=VALUE(RIGHT(I$1,4))),Table1[Value],"Not found"))} -> -33
B35: {=IF($A35="","",_xlfn.XLOOKUP(1,(Table1[Line Item]=$A35)*(Table1[Fiscal Year]=VALUE(RIGHT(B$1,4))),Table1[Value],"Not found"))} | C35: {=IF($A35="","",_xlfn.XLOOKUP(1,(Table1[Line Item]=$A35)*(Table1[Fiscal Year]=VALUE(RIGHT(C$1,4))),Table1[Value],"Not found"))} | D35: {=IF($A35="","",_xlfn.XLOOKUP(1,(Table1[Line Item]=$A35)*(Table1[Fiscal Year]=VALUE(RIGHT(D$1,4))),Table1[Value],"Not found"))} | E35: {=IF($A35="","",_xlfn.XLOOKUP(1,(Table1[Line Item]=$A35)*(Table1[Fiscal Year]=VALUE(RIGHT(E$1,4))),Table1[Value],"Not found"))} | F35: {=IF($A35="","",_xlfn.XLOOKUP(1,(Table1[Line Item]=$A35)*(Table1[Fiscal Year]=VALUE(RIGHT(F$1,4))),Table1[Value],"Not found"))} | G35: {=IF($A35="","",_xlfn.XLOOKUP(1,(Table1[Line Item]=$A35)*(Table1[Fiscal Year]=VALUE(RIGHT(G$1,4))),Table1[Value],"Not found"))} | H35: {=IF($A35="","",_xlfn.XLOOKUP(1,(Table1[Line Item]=$A35)*(Table1[Fiscal Year]=VALUE(RIGHT(H$1,4))),Table1[Value],"Not found"))} | I35: {=IF($A35="","",_xlfn.XLOOKUP(1,(Table1[Line Item]=$A35)*(Table1[Fiscal Year]=VALUE(RIGHT(I$1,4))),Table1[Value],"Not found"))}
A36: basic eps | B36: {=IF($A36="","",_xlfn.XLOOKUP(1,(Table1[Line Item]=$A36)*(Table1[Fiscal Year]=VALUE(RIGHT(B$1,4))),Table1[Value],"Not found"))} -> 4.72 | C36: {=IF($A36="","",_xlfn.XLOOKUP(1,(Table1[Line Item]=$A36)*(Table1[Fiscal Year]=VALUE(RIGHT(C$1,4))),Table1[Value],"Not found"))} -> 6.78 | D36: {=IF($A36="","",_xlfn.XLOOKUP(1,(Table1[Line Item]=$A36)*(Table1[Fiscal Year]=VALUE(RIGHT(D$1,4))),Table1[Value],"Not found"))} -> 8.45 | E36: {=IF($A36="","",_xlfn.XLOOKUP(1,(Table1[Line Item]=$A36)*(Table1[Fiscal Year]=VALUE(RIGHT(E$1,4))),Table1[Value],"Not found"))} -> 9.48 | F36: {=IF($A36="","",_xlfn.XLOOKUP(1,(Table1[Line Item]=$A36)*(Table1[Fiscal Year]=VALUE(RIGHT(F$1,4))),Table1[Value],"Not found"))} -> 1.79 | G36: {=IF($A36="","",_xlfn.XLOOKUP(1,(Table1[Line Item]=$A36)*(Table1[Fiscal Year]=VALUE(RIGHT(G$1,4))),Table1[Value],"Not found"))} -> 7.39 | H36: {=IF($A36="","",_xlfn.XLOOKUP(1,(Table1[Line Item]=$A36)*(Table1[Fiscal Year]=VALUE(RIGHT(H$1,4))),Table1[Value],"Not found"))} -> 0.27 | I36: {=IF($A36="","",_xlfn.XLOOKUP(1,(Table1[Line Item]=$A36)*(Table1[Fiscal Year]=VALUE(RIGHT(I$1,4))),Table1[Value],"Not found"))} -> -0.18
A37: diluted eps | B37: {=IF($A37="","",_xlfn.XLOOKUP(1,(Table1[Line Item]=$A37)*(Table1[Fiscal Year]=VALUE(RIGHT(B$1,4))),Table1[Value],"Not found"))} -> 4.7 | C37: {=IF($A37="","",_xlfn.XLOOKUP(1,(Table1[Line Item]=$A37)*(Table1[Fiscal Year]=VALUE(RIGHT(C$1,4))),Table1[Value],"Not found"))} -> 6.75 | D37: {=IF($A37="","",_xlfn.XLOOKUP(1,(Table1[Line Item]=$A37)*(Table1[Fiscal Year]=VALUE(RIGHT(D$1,4))),Table1[Value],"Not found"))} -> 8.42 | E37: {=IF($A37="","",_xlfn.XLOOKUP(1,(Table1[Line Item]=$A37)*(Table1[Fiscal Year]=VALUE(RIGHT(E$1,4))),Table1[Value],"Not found"))} -> 9.44 | F37: {=IF($A37="","",_xlfn.XLOOKUP(1,(Table1[Line Item]=$A37)*(Table1[Fiscal Year]=VALUE(RIGHT(F$1,4))),Table1[Value],"Not found"))} -> 1.78 | G37: {=IF($A37="","",_xlfn.XLOOKUP(1,(Table1[Line Item]=$A37)*(Table1[Fiscal Year]=VALUE(RIGHT(G$1,4))),Table1[Value],"Not found"))} -> 7.36 | H37: {=IF($A37="","",_xlfn.XLOOKUP(1,(Table1[Line Item]=$A37)*(Table1[Fiscal Year]=VALUE(RIGHT(H$1,4))),Table1[Value],"Not found"))} -> 0.27 | I37: {=IF($A37="","",_xlfn.XLOOKUP(1,(Table1[Line Item]=$A37)*(Table1[Fiscal Year]=VALUE(RIGHT(I$1,4))),Table1[Value],"Not found"))} -> -0.18
A38: wtd. avg shares - basic (mn) | B38: {=IF($A38="","",_xlfn.XLOOKUP(1,(Table1[Line Item]=$A38)*(Table1[Fiscal Year]=VALUE(RIGHT(B$1,4))),Table1[Value],"Not found"))} -> 201 | C38: {=IF($A38="","",_xlfn.XLOOKUP(1,(Table1[Line Item]=$A38)*(Table1[Fiscal Year]=VALUE(RIGHT(C$1,4))),Table1[Value],"Not found"))} -> 202.5 | D38: {=IF($A38="","",_xlfn.XLOOKUP(1,(Table1[Line Item]=$A38)*(Table1[Fiscal Year]=VALUE(RIGHT(D$1,4))),Table1[Value],"Not found"))} -> 200 | E38: {=IF($A38="","",_xlfn.XLOOKUP(1,(Table1[Line Item]=$A38)*(Table1[Fiscal Year]=VALUE(RIGHT(E$1,4))),Table1[Value],"Not found"))} -> 195.7 | F38: {=IF($A38="","",_xlfn.XLOOKUP(1,(Table1[Line Item]=$A38)*(Table1[Fiscal Year]=VALUE(RIGHT(F$1,4))),Table1[Value],"Not found"))} -> 194.3 | G38: {=IF($A38="","",_xlfn.XLOOKUP(1,(Table1[Line Item]=$A38)*(Table1[Fiscal Year]=VALUE(RIGHT(G$1,4))),Table1[Value],"Not found"))} -> 195.8 | H38: {=IF($A38="","",_xlfn.XLOOKUP(1,(Table1[Line Item]=$A38)*(Table1[Fiscal Year]=VALUE(RIGHT(H$1,4))),Table1[Value],"Not found"))} -> 183.5 | I38: {=IF($A38="","",_xlfn.XLOOKUP(1,(Table1[Line Item]=$A38)*(Table1[Fiscal Year]=VALUE(RIGHT(I$1,4))),Table1[Value],"Not found"))} -> 178.6
A39: wtd. avg shares - diluted (mn) | B39: {=IF($A39="","",_xlfn.XLOOKUP(1,(Table1[Line Item]=$A39)*(Table1[Fiscal Year]=VALUE(RIGHT(B$1,4))),Table1[Value],"Not found"))} -> 201.8 | C39: {=IF($A39="","",_xlfn.XLOOKUP(1,(Table1[Line Item]=$A39)*(Table1[Fiscal Year]=VALUE(RIGHT(C$1,4))),Table1[Value],"Not found"))} -> 203.3 | D39: {=IF($A39="","",_xlfn.XLOOKUP(1,(Table1[Line Item]=$A39)*(Table1[Fiscal Year]=VALUE(RIGHT(D$1,4))),Table1[Value],"Not found"))} -> 200.8 | E39: {=IF($A39="","",_xlfn.XLOOKUP(1,(Table1[Line Item]=$A39)*(Table1[Fiscal Year]=VALUE(RIGHT(E$1,4))),Table1[Value],"Not found"))} -> 196.5 | F39: {=IF($A39="","",_xlfn.XLOOKUP(1,(Table1[Line Item]=$A39)*(Table1[Fiscal Year]=VALUE(RIGHT(F$1,4))),Table1[Value],"Not found"))} -> 195.1 | G39: {=IF($A39="","",_xlfn.XLOOKUP(1,(Table1[Line Item]=$A39)*(Table1[Fiscal Year]=VALUE(RIGHT(G$1,4))),Table1[Value],"Not found"))} -> 196.6 | H39: {=IF($A39="","",_xlfn.XLOOKUP(1,(Table1[Line Item]=$A39)*(Table1[Fiscal Year]=VALUE(RIGHT(H$1,4))),Table1[Value],"Not found"))} -> 184.2 | I39: {=IF($A39="","",_xlfn.XLOOKUP(1,(Table1[Line Item]=$A39)*(Table1[Fiscal Year]=VALUE(RIGHT(I$1,4))),Table1[Value],"Not found"))} -> 179.3
A40: dividend per share (dps) | B40: {=IF($A40="","",_xlfn.XLOOKUP(1,(Table1[Line Item]=$A40)*(Table1[Fiscal Year]=VALUE(RIGHT(B$1,4))),Table1[Value],"Not found"))} -> 2 | C40: {=IF($A40="","",_xlfn.XLOOKUP(1,(Table1[Line Item]=$A40)*(Table1[Fiscal Year]=VALUE(RIGHT(C$1,4))),Table1[Value],"Not found"))} -> 2.6 | D40: {=IF($A40="","",_xlfn.XLOOKUP(1,(Table1[Line Item]=$A40)*(Table1[Fiscal Year]=VALUE(RIGHT(D$1,4))),Table1[Value],"Not found"))} -> 3.35 | E40: {=IF($A40="","",_xlfn.XLOOKUP(1,(Table1[Line Item]=$A40)*(Table1[Fiscal Year]=VALUE(RIGHT(E$1,4))),Table1[Value],"Not found"))} -> 3.85 | F40: {=IF($A40="","",_xlfn.XLOOKUP(1,(Table1[Line Item]=$A40)*(Table1[Fiscal Year]=VALUE(RIGHT(F$1,4))),Table1[Value],"Not found"))} -> 0 | G40: {=IF($A40="","",_xlfn.XLOOKUP(1,(Table1[Line Item]=$A40)*(Table1[Fiscal Year]=VALUE(RIGHT(G$1,4))),Table1[Value],"Not found"))} -> 3.3 | H40: {=IF($A40="","",_xlfn.XLOOKUP(1,(Table1[Line Item]=$A40)*(Table1[Fiscal Year]=VALUE(RIGHT(H$1,4))),Table1[Value],"Not found"))} -> 0.7 | I40: {=IF($A40="","",_xlfn.XLOOKUP(1,(Table1[Line Item]=$A40)*(Table1[Fiscal Year]=VALUE(RIGHT(I$1,4))),Table1[Value],"Not found"))} -> 0.7

Sheet Trend Analysis(Stage4-Q1)
A1: Fiscal Year | B1: FY2016 | C1: FY2017 | D1: FY2018 | E1: FY2019 | F1: FY2020 | G1: FY2021 | H1: FY2022 | I1: FY2023
A2: Revenue YoY | B2: N/A | C2: =('MASTER P&L'!C$6-'MASTER P&L'!B$6)/'MASTER P&L'!B$6 -> 0.14797381 | D2: =('MASTER P&L'!D$6-'MASTER P&L'!C$6)/'MASTER P&L'!C$6 -> 0.032849467 | E2: =('MASTER P&L'!E$6-'MASTER P&L'!D$6)/'MASTER P&L'!D$6 -> 0.07871321 | F2: =('MASTER P&L'!F$6-'MASTER P&L'!E$6)/'MASTER P&L'!E$6 -> -0.1605753 | G2: =('MASTER P&L'!G$6-'MASTER P&L'!F$6)/'MASTER P&L'!F$6 -> 0.070046362 | H2: =('MASTER P&L'!H$6-'MASTER P&L'!G$6)/'MASTER P&L'!G$6 -> 0.060139399 | I2: =('MASTER P&L'!I$6-'MASTER P&L'!H$6)/'MASTER P&L'!H$6 -> -0.048154236
A3: Gross Profit YoY | B3: N/A | C3: =('MASTER P&L'!C$10-'MASTER P&L'!B$10)/'MASTER P&L'!B$10 -> 0.19047089 | D3: =('MASTER P&L'!D$10-'MASTER P&L'!C$10)/'MASTER P&L'!C$10 -> 0.057415373 | E3: =('MASTER P&L'!E$10-'MASTER P&L'!D$10)/'MASTER P&L'!D$10 -> 0.087106473 | F3: =('MASTER P&L'!F$10-'MASTER P&L'!E$10)/'MASTER P&L'!E$10 -> -0.19775482 | G3: =('MASTER P&L'!G$10-'MASTER P&L'!F$10)/'MASTER P&L'!F$10 -> 0.087304806 | H3: =('MASTER P&L'!H$10-'MASTER P&L'!G$10)/'MASTER P&L'!G$10 -> -0.0069943113 | I3: =('MASTER P&L'!I$10-'MASTER P&L'!H$10)/'MASTER P&L'!H$10 -> -0.044139745
A4: EBIT YoY | B4: N/A | C4: =('MASTER P&L'!C$22-'MASTER P&L'!B$22)/'MASTER P&L'!B$22 -> 0.41080313 | D4: =('MASTER P&L'!D$22-'MASTER P&L'!C$22)/'MASTER P&L'!C$22 -> 0.18942065 | E4: =('MASTER P&L'!E$22-'MASTER P&L'!D$22)/'MASTER P&L'!D$22 -> 0.10969928 | F4: =('MASTER P&L'!F$22-'MASTER P&L'!E$22)/'MASTER P&L'!E$22 -> -0.69351145 | G4: =('MASTER P&L'!G$22-'MASTER P&L'!F$22)/'MASTER P&L'!F$22 -> 1.2914072 | H4: =('MASTER P&L'!H$22-'MASTER P&L'!G$22)/'MASTER P&L'!G$22 -> -0.78967391 | I4: =('MASTER P&L'!I$22-'MASTER P&L'!H$22)/'MASTER P&L'!H$22 -> -0.082687339
A5: Net Income YoY | B5: N/A | C5: =('MASTER P&L'!C$32-'MASTER P&L'!B$32)/'MASTER P&L'!B$32 -> 0.44328824 | D5: =('MASTER P&L'!D$32-'MASTER P&L'!C$32)/'MASTER P&L'!C$32 -> 0.22638789 | E5: =('MASTER P&L'!E$32-'MASTER P&L'!D$32)/'MASTER P&L'!D$32 -> 0.095825985 | F5: =('MASTER P&L'!F$32-'MASTER P&L'!E$32)/'MASTER P&L'!E$32 -> -0.81062232 | G5: =('MASTER P&L'!G$32-'MASTER P&L'!F$32)/'MASTER P&L'!F$32 -> 3.121813 | H5: =('MASTER P&L'!H$32-'MASTER P&L'!G$32)/'MASTER P&L'!G$32 -> -0.96013746 | I5: =('MASTER P&L'!I$32-'MASTER P&L'!H$32)/'MASTER P&L'!H$32 -> -1.4482759
A13: FY2017 Revenue YoY=
A14: (FY2017 Revenue - FY2016 Revenue) / FY2016 Revenue
A16: FY2017 Gross Profit YoY=
A17: (FY2017 Gross Profit - FY2016 Gross Profit) / FY2016 Gross Profit
A19: FY2017 EBIT YoY=
A20: (FY2017 EBIT - FY2016 EBIT) / FY2016 EBIT
A22: FY2017 Net Income YoY=
A23: (FY2017 Net Income - FY2016 Net Income) / FY2016 Net Income

Sheet CAGR(Stage4-Q2)
A1: CAGR=((ending value/Beginning value )^1/n ) -1 | J1: Revenue CAGR
J2: (FY2023 Revenue/FY2016 Revenue)^(1/7)-1 | O2: Metric | P2: FY2016 | Q2: FY2023 | R2: CAGR
O3: Revenue | P3: ='MASTER P&L'!B6 -> 18483 | Q3: ='MASTER P&L'!I6 -> 21427 | R3: 0.0213
A4: You have FY2016 → FY2023, which is 7 years | J4: =(Q3/P3) -> 1.1592815 | O4: Net Income (Total) | P4: 961 | Q4: -26 | R4: N/M
J5: =(J4)^(1/7) -> 1.0213388
A6: FY2016 → FY2017 = 1 | J6: =J5-1 -> 0.02133883
A7: FY2017 → FY2018 = 2 | J7: 0.0213
A8: FY2018 → FY2019 = 3
A9: FY2019 → FY2020 = 4
A10: FY2020 → FY2021 = 5
A11: FY2021 → FY2022 = 6
A12: FY2022 → FY2023 = 7 | J12: Net Income CAGR
J14: (FY2023 Net Income/FY2016 Net Income)^(1/7)-1
J16: =(Q4/P4) -> -0.027055151
J17: =(J16)^(1/7) -> -0.59708438
J18: =J17-1 -> -1.5970844

Sheet Index Tables(Stage4-Q3)
A1: Fiscal Year | B1: FY2016 | C1: FY2017 | D1: FY2018 | E1: FY2019 | F1: FY2020 | G1: FY2021 | H1: FY2022 | I1: FY2023
A2: Revenue Index | B2: 100 | C2: =('MASTER P&L'!C$6/'MASTER P&L'!$B$6)*100 -> 114.79738 | D2: =('MASTER P&L'!D$6/'MASTER P&L'!$B$6)*100 -> 118.56841 | E2: =('MASTER P&L'!E$6/'MASTER P&L'!$B$6)*100 -> 127.90131 | F2: =('MASTER P&L'!F$6/'MASTER P&L'!$B$6)*100 -> 107.36352 | G2: =('MASTER P&L'!G$6/'MASTER P&L'!$B$6)*100 -> 114.88395 | H2: =('MASTER P&L'!H$6/'MASTER P&L'!$B$6)*100 -> 121.793 | I2: =('MASTER P&L'!I$6/'MASTER P&L'!$B$6)*100 -> 115.92815
A3: Gross Profit Index | B3: 100 | C3: =('MASTER P&L'!C$10/'MASTER P&L'!$B$10)*100 -> 119.04709 | D3: =('MASTER P&L'!D$10/'MASTER P&L'!$B$10)*100 -> 125.88222 | E3: =('MASTER P&L'!E$10/'MASTER P&L'!$B$10)*100 -> 136.84738 | F3: =('MASTER P&L'!F$10/'MASTER P&L'!$B$10)*100 -> 109.78515 | G3: =('MASTER P&L'!G$10/'MASTER P&L'!$B$10)*100 -> 119.36992 | H3: =('MASTER P&L'!H$10/'MASTER P&L'!$B$10)*100 -> 118.53501 | I3: =('MASTER P&L'!I$10/'MASTER P&L'!$B$10)*100 -> 113.30291 | J3: Formula=Current year's value ÷ FY2016 value × 100
A4: Operating Expenses Index | B4: 100 | C4: =('MASTER P&L'!C$19/'MASTER P&L'!$B$19)*100 -> 114.79855 | D4: =('MASTER P&L'!D$19/'MASTER P&L'!$B$19)*100 -> 118.01395 | E4: =('MASTER P&L'!E$19/'MASTER P&L'!$B$19)*100 -> 127.59556 | F4: =('MASTER P&L'!F$19/'MASTER P&L'!$B$19)*100 -> 118.89205 | G4: =('MASTER P&L'!G$19/'MASTER P&L'!$B$19)*100 -> 116.8001 | H4: =('MASTER P&L'!H$19/'MASTER P&L'!$B$19)*100 -> 132.25723 | I4: =('MASTER P&L'!I$19/'MASTER P&L'!$B$19)*100 -> 128.93853
J5: The whole purpose of an index is to measure every year against the same base year, FY2016
H11: The indexed series shows that revenue increased to 115.93 by FY2023, while gross profit reached 113.30. In contrast, operating expenses rose to 128.94, growing substantially faster than both revenue and gross profit. This divergence indicates increasing operating-cost pressure and suggests weaker operating leverage over the period. The sharp movements around FY2020 and FY2021 also show that the business experienced a significant disruption followed by a recovery.

Sheet Stage4-Q4
A1: Metric | B1: Best Year | C1: Best Value | D1: Worst Year | E1: Worst Value
A2: Revenue | B2: =_xlfn.XLOOKUP(C2,'MASTER P&L'!B6:I6,'MASTER P&L'!B1:I1) -> FY2019 | C2: =MAX('MASTER P&L'!B6:I6) -> 23640 | D2: =_xlfn.XLOOKUP(E2,'MASTER P&L'!B6:I6,'MASTER P&L'!B1:I1) -> FY2016 | E2: =MIN('MASTER P&L'!B6:I6) -> 18483
A3: Operating Profit (EBIT) | B3: =_xlfn.XLOOKUP(C3,'MASTER P&L'!B22:I22,'MASTER P&L'!B1:I1) -> FY2019 | C3: =MAX('MASTER P&L'!B22:I22) -> 2620 | D3: =_xlfn.XLOOKUP(E3,'MASTER P&L'!B22:I22,'MASTER P&L'!B1:I1) -> FY2023 | E3: =MIN('MASTER P&L'!B22:I22) -> 355 | H3: Basic EPS=Net income attributable to ordinary shareholders/Weighted average basic shares
A4: Basic EPS | B4: =_xlfn.XLOOKUP(C4,'MASTER P&L'!B36:I36,'MASTER P&L'!$B1:$I1) -> FY2019 | C4: =MAX('MASTER P&L'!B36:I36) -> 9.48 | D4: =_xlfn.XLOOKUP(E4,'MASTER P&L'!B36:I36,'MASTER P&L'!$B1:$I1) -> FY2023 | E4: =MIN('MASTER P&L'!B36:I36) -> -0.18

Sheet Stage4-Q5
A1: Revenue growth=(Revenue2023/Revenue2016)−1
G3: =('MASTER P&L'!I6/'MASTER P&L'!B6)-1 -> 0.1592815 | J3: This indicates weakening operating leverage over the period, as the business incurred substantially higher operating costs relative to its revenue growth. In other words, the company did not achieve sufficient revenue growth to absorb the increase in operating expenses, putting pressure on operating profitability.
A8: Operating expense growth=(OpEx2023/OpEx2016)−1
G10: =('MASTER P&L'!I19/'MASTER P&L'!B19)-1 -> 0.28938533

Sheet Stage 5 -Q1
A1: ratios | B1: FY2016 | C1: FY2017 | D1: FY2018 | E1: FY2019 | F1: FY2020 | G1: FY2021 | H1: FY2022 | I1: FY2023
A2: Gross Margin % = Gross Profit ÷ Total Net Revenue | B2: =('MASTER P&L'!B$10/'MASTER P&L'!B$6)*100 -> 48.601418 | C2: =('MASTER P&L'!C$10/'MASTER P&L'!C$6)*100 -> 50.400603 | D2: =('MASTER P&L'!D$10/'MASTER P&L'!D$6)*100 -> 51.599361 | E2: =('MASTER P&L'!E$10/'MASTER P&L'!E$6)*100 -> 52.000846 | F2: =('MASTER P&L'!F$10/'MASTER P&L'!F$6)*100 -> 49.697642 | G2: =('MASTER P&L'!G$10/'MASTER P&L'!G$6)*100 -> 50.499199 | H2: =('MASTER P&L'!H$10/'MASTER P&L'!H$6)*100 -> 47.301319 | I2: =('MASTER P&L'!I$10/'MASTER P&L'!I$6)*100 -> 47.500817
A3: Operating Margin % = EBIT ÷ Total Net Revenue | B3: =('MASTER P&L'!B$22/'MASTER P&L'!B$6)*100 -> 7.6124006 | C3: =('MASTER P&L'!C$22/'MASTER P&L'!C$6)*100 -> 9.3552644 | D3: =('MASTER P&L'!D$22/'MASTER P&L'!D$6)*100 -> 10.773443 | E3: =('MASTER P&L'!E$22/'MASTER P&L'!E$6)*100 -> 11.08291 | F3: =('MASTER P&L'!F$22/'MASTER P&L'!F$6)*100 -> 4.0465632 | G3: =('MASTER P&L'!G$22/'MASTER P&L'!G$6)*100 -> 8.665348 | H3: =('MASTER P&L'!H$22/'MASTER P&L'!H$6)*100 -> 1.7191595 | I3: =('MASTER P&L'!I$22/'MASTER P&L'!I$6)*100 -> 1.6567882
A4: Net Margin % = Net Income Attrib. to Shareholders ÷ Total Net Revenue | B4: =('MASTER P&L'!B$34/'MASTER P&L'!B$6)*100 -> 5.1344479 | C4: =('MASTER P&L'!C$34/'MASTER P&L'!C$6)*100 -> 6.4709209 | D4: =('MASTER P&L'!D$34/'MASTER P&L'!D$6)*100 -> 7.7116131 | E4: =('MASTER P&L'!E$34/'MASTER P&L'!E$6)*100 -> 7.8468697 | F4: =('MASTER P&L'!F$34/'MASTER P&L'!F$6)*100 -> 1.7486394 | G4: =('MASTER P&L'!G$34/'MASTER P&L'!G$6)*100 -> 6.8145427 | H4: =('MASTER P&L'!H$34/'MASTER P&L'!H$6)*100 -> 0.22211363 | I4: =('MASTER P&L'!I$34/'MASTER P&L'!I$6)*100 -> -0.15401129

Sheet Stage5-Q2
A1: FY2019 → starting point FY2023 → ending point | D1: 1. Gross Margin change | I1: 3. Calculate the change
E2: FY2023 Gross Margin % - FY2019 Gross Margin %
F3: ='Stage 5 -Q1'!$I$2-'Stage 5 -Q1'!$E$2 -> -4.5000293 | J3: Line | K3: FY2019 calculation | L3: FY2023 calculation | M3: Change (pp)
J4: Marketing & Point-of-Sale | K4: =(ABS('MASTER P&L'!E15)/'MASTER P&L'!E6)*100 -> 12.800338 | L4: =(ABS('MASTER P&L'!I15)/'MASTER P&L'!I6)*100 -> 12.302235 | M4: =L4-K4 -> -0.49810291
J5: Distribution & Selling | K5: =(ABS('MASTER P&L'!E16)/'MASTER P&L'!E6)*100 -> 22.301184 | L5: =(ABS('MASTER P&L'!I16)/'MASTER P&L'!I6)*100 -> 25.799225 | M5: =L5-K5 -> 3.4980408
J6: General & Administration | K6: =(ABS('MASTER P&L'!E17)/'MASTER P&L'!E6)*100 -> 5.6979695 | L6: =(ABS('MASTER P&L'!I17)/'MASTER P&L'!I6)*100 -> 7.2992019 | M6: =L6-K6 -> 1.6012324
J7: Sundry Expenses | K7: =(ABS('MASTER P&L'!E18)/'MASTER P&L'!E6)*100 -> 0.99830795 | L7: =(ABS('MASTER P&L'!I18)/'MASTER P&L'!I6)*100 -> 1.1994213 | M7: =L7-K7 -> 0.20111334
A8: 2. Each operating expense as % of revenue
C11: Expense / Total Net Revenue * 100 | I11: 4. Find the biggest damage
C12: Marketing FY2019 / Revenue FY2019 * 100
C13: Marketing FY2023 / Revenue FY2023 * 100
J14: Distribution & Selling Expense had the biggest negative impact, increasing by 3.50 percentage points of revenue from FY2019 to FY2023.
B16: Line | C16: FY2019 calculation | D16: FY2023 calculation
B17: Marketing & Point-of-Sale | C17: =(ABS('MASTER P&L'!E15)/'MASTER P&L'!E6)*100 -> 12.800338 | D17: =(ABS('MASTER P&L'!I15)/'MASTER P&L'!I6)*100 -> 12.302235
B18: Distribution & Selling | C18: =(ABS('MASTER P&L'!E16)/'MASTER P&L'!E6)*100 -> 22.301184 | D18: =(ABS('MASTER P&L'!I16)/'MASTER P&L'!I6)*100 -> 25.799225
B19: General & Administration | C19: =(ABS('MASTER P&L'!E17)/'MASTER P&L'!E6)*100 -> 5.6979695 | D19: =(ABS('MASTER P&L'!I17)/'MASTER P&L'!I6)*100 -> 7.2992019
B20: Sundry Expenses | C20: =(ABS('MASTER P&L'!E18)/'MASTER P&L'!E6)*100 -> 0.99830795 | D20: =(ABS('MASTER P&L'!I18)/'MASTER P&L'!I6)*100 -> 1.1994213

Sheet Stage5-Q3
A1: % OF NET SALES | B1: FY2016 calculation | C1: FY2017 calculation | D1: FY2018 calculation | E1: FY2019 calculation | F1: FY2020 calculation | G1: FY2021 calculation | H1: FY2022 calculation | I1: FY2023 calculation
A2: Marketing & Point-of-Sale | B2: =(ABS('MASTER P&L'!B$15)/'MASTER P&L'!B$6) -> 0.13699075 | C2: =(ABS('MASTER P&L'!C$15)/'MASTER P&L'!C$6) -> 0.13399001 | D2: =(ABS('MASTER P&L'!D$15)/'MASTER P&L'!D$6) -> 0.13100616 | E2: =(ABS('MASTER P&L'!E$15)/'MASTER P&L'!E$6) -> 0.12800338 | F2: =(ABS('MASTER P&L'!F$15)/'MASTER P&L'!F$6) -> 0.11897803 | G2: =(ABS('MASTER P&L'!G$15)/'MASTER P&L'!G$6) -> 0.12098521 | H2: =(ABS('MASTER P&L'!H$15)/'MASTER P&L'!H$6) -> 0.12398383 | I2: =(ABS('MASTER P&L'!I$15)/'MASTER P&L'!I$6) -> 0.12302235
A3: Distribution & Selling | B3: =(ABS('MASTER P&L'!B$16)/'MASTER P&L'!B$6) -> 0.21798409 | C3: =(ABS('MASTER P&L'!C$16)/'MASTER P&L'!C$6) -> 0.22198134 | D3: =(ABS('MASTER P&L'!D$16)/'MASTER P&L'!D$6) -> 0.22400183 | E3: =(ABS('MASTER P&L'!E$16)/'MASTER P&L'!E$6) -> 0.22301184 | F3: =(ABS('MASTER P&L'!F$16)/'MASTER P&L'!F$6) -> 0.27000605 | G3: =(ABS('MASTER P&L'!G$16)/'MASTER P&L'!G$6) -> 0.23401149 | H3: =(ABS('MASTER P&L'!H$16)/'MASTER P&L'!H$6) -> 0.24299231 | I3: =(ABS('MASTER P&L'!I$16)/'MASTER P&L'!I$6) -> 0.25799225
A4: General & Administration | B4: =(ABS('MASTER P&L'!B$17)/'MASTER P&L'!B$6) -> 0.053995563 | C4: =(ABS('MASTER P&L'!C$17)/'MASTER P&L'!C$6) -> 0.05302102 | D4: =(ABS('MASTER P&L'!D$17)/'MASTER P&L'!D$6) -> 0.052019165 | E4: =(ABS('MASTER P&L'!E$17)/'MASTER P&L'!E$6) -> 0.056979695 | F4: =(ABS('MASTER P&L'!F$17)/'MASTER P&L'!F$6) -> 0.065007055 | G4: =(ABS('MASTER P&L'!G$17)/'MASTER P&L'!G$6) -> 0.060987096 | H4: =(ABS('MASTER P&L'!H$17)/'MASTER P&L'!H$6) -> 0.078006308 | I4: =(ABS('MASTER P&L'!I$17)/'MASTER P&L'!I$6) -> 0.072992019
